2024-03-14 17:43:00,297.297 [ERROR] [Commom.py:35] 预料之外的错误: Traceback (most recent call last):
  File "/opt/anaconda3/envs/ms/lib/python3.9/tkinter/__init__.py", line 1892, in __call__
    return self.func(*args)
  File "/Users/gml/Downloads/Route_design/main.py", line 584, in save_1
    sava(checkvar)
  File "/Users/gml/Downloads/Route_design/main.py", line 620, in sava
    img.save(png_path)
  File "/opt/anaconda3/envs/ms/lib/python3.9/site-packages/PIL/Image.py", line 2394, in save
    self._ensure_mutable()
  File "/opt/anaconda3/envs/ms/lib/python3.9/site-packages/PIL/Image.py", line 611, in _ensure_mutable
    self._copy()
  File "/opt/anaconda3/envs/ms/lib/python3.9/site-packages/PIL/Image.py", line 604, in _copy
    self.load()
  File "/opt/anaconda3/envs/ms/lib/python3.9/site-packages/PIL/EpsImagePlugin.py", line 343, in load
    self.im = Ghostscript(self.tile, self.size, self.fp, scale, transparency)
  File "/opt/anaconda3/envs/ms/lib/python3.9/site-packages/PIL/EpsImagePlugin.py", line 146, in Ghostscript
    subprocess.check_call(command, startupinfo=startupinfo)
  File "/opt/anaconda3/envs/ms/lib/python3.9/subprocess.py", line 373, in check_call
    raise CalledProcessError(retcode, cmd)
subprocess.CalledProcessError: Command '['gs', '-q', '-g931x682', '-r72.000000x72.000000', '-dBATCH', '-dNOPAUSE', '-dSAFER', '-sDEVICE=ppmraw', '-sOutputFile=/var/folders/hc/8d2tfbp90yx8nwp0fz41qkt00000gn/T/tmpawbjixvz', '-c', '159 -55 translate', '-f', '/Users/gml/Downloads/Route_design/ms_download/路线设计_20240314-174253.eps', '-c', 'showpage']' died with <Signals.SIGABRT: 6>.
Traceback (most recent call last):
  File "/opt/anaconda3/envs/ms/lib/python3.9/tkinter/__init__.py", line 1892, in __call__
    return self.func(*args)
  File "/Users/gml/Downloads/Route_design/main.py", line 584, in save_1
    sava(checkvar)
  File "/Users/gml/Downloads/Route_design/main.py", line 620, in sava
    img.save(png_path)
  File "/opt/anaconda3/envs/ms/lib/python3.9/site-packages/PIL/Image.py", line 2394, in save
    self._ensure_mutable()
  File "/opt/anaconda3/envs/ms/lib/python3.9/site-packages/PIL/Image.py", line 611, in _ensure_mutable
    self._copy()
  File "/opt/anaconda3/envs/ms/lib/python3.9/site-packages/PIL/Image.py", line 604, in _copy
    self.load()
  File "/opt/anaconda3/envs/ms/lib/python3.9/site-packages/PIL/EpsImagePlugin.py", line 343, in load
    self.im = Ghostscript(self.tile, self.size, self.fp, scale, transparency)
  File "/opt/anaconda3/envs/ms/lib/python3.9/site-packages/PIL/EpsImagePlugin.py", line 146, in Ghostscript
    subprocess.check_call(command, startupinfo=startupinfo)
  File "/opt/anaconda3/envs/ms/lib/python3.9/subprocess.py", line 373, in check_call
    raise CalledProcessError(retcode, cmd)
subprocess.CalledProcessError: Command '['gs', '-q', '-g931x682', '-r72.000000x72.000000', '-dBATCH', '-dNOPAUSE', '-dSAFER', '-sDEVICE=ppmraw', '-sOutputFile=/var/folders/hc/8d2tfbp90yx8nwp0fz41qkt00000gn/T/tmpawbjixvz', '-c', '159 -55 translate', '-f', '/Users/gml/Downloads/Route_design/ms_download/路线设计_20240314-174253.eps', '-c', 'showpage']' died with <Signals.SIGABRT: 6>.
2024-03-14 18:04:31,673.673 [WARNING] [scale.py:40] 'list' object has no attribute 'x'
2024-03-14 18:04:32,719.719 [WARNING] [scale.py:40] 'list' object has no attribute 'x'
2024-03-14 18:04:52,057.057 [WARNING] [scale.py:40] 'list' object has no attribute 'x'
2024-03-14 18:04:52,726.726 [WARNING] [scale.py:40] 'list' object has no attribute 'x'
2024-03-14 18:04:54,657.657 [ERROR] [Commom.py:35] 预料之外的错误: Traceback (most recent call last):
  File "/opt/anaconda3/envs/ms/lib/python3.9/site-packages/PIL/Image.py", line 3231, in open
    fp.seek(0)
AttributeError: 'str' object has no attribute 'seek'

During handling of the above exception, another exception occurred:

Traceback (most recent call last):
  File "/opt/anaconda3/envs/ms/lib/python3.9/tkinter/__init__.py", line 1892, in __call__
    return self.func(*args)
  File "/Users/gml/Downloads/Route_design/main.py", line 797, in custom
    CreateImg(canvas, index_img, img_path).create()
  File "/Users/gml/Downloads/Route_design/scale.py", line 119, in __init__
    self.img_obj = Image.open(self.img_path)
  File "/opt/anaconda3/envs/ms/lib/python3.9/site-packages/PIL/Image.py", line 3233, in open
    fp = io.BytesIO(fp.read())
AttributeError: 'str' object has no attribute 'read'
Traceback (most recent call last):
  File "/opt/anaconda3/envs/ms/lib/python3.9/site-packages/PIL/Image.py", line 3231, in open
    fp.seek(0)
AttributeError: 'str' object has no attribute 'seek'

During handling of the above exception, another exception occurred:

Traceback (most recent call last):
  File "/opt/anaconda3/envs/ms/lib/python3.9/tkinter/__init__.py", line 1892, in __call__
    return self.func(*args)
  File "/Users/gml/Downloads/Route_design/main.py", line 797, in custom
    CreateImg(canvas, index_img, img_path).create()
  File "/Users/gml/Downloads/Route_design/scale.py", line 119, in __init__
    self.img_obj = Image.open(self.img_path)
  File "/opt/anaconda3/envs/ms/lib/python3.9/site-packages/PIL/Image.py", line 3233, in open
    fp = io.BytesIO(fp.read())
AttributeError: 'str' object has no attribute 'read'
2024-03-14 18:04:56,502.502 [WARNING] [scale.py:40] 'list' object has no attribute 'x'
2024-04-18 15:52:58,063.063 [WARNING] [scale.py:40] 'list' object has no attribute 'x'
